Workbook

Sheet Tabelle5

Sheet Tabelle8
A3: Anzahl von Gerätenummer | B3: Spaltenbeschriftungen
A4: Zeilenbeschriftungen | B4: Berlin | C4: Hamburg | D4: München | E4: Gesamtergebnis
A5: Beamer | B5: 7 | C5: 3 | D5: 2 | E5: 12
A6: Drucker | B6: 9 | C6: 2 | D6: 1 | E6: 12
A7: Laptop | C7: 4 | D7: 6 | E7: 10
A8: Monitor | B8: 2 | D8: 2 | E8: 4
A9: Smartphone | D9: 4 | E9: 4
A10: Tablet | C10: 2 | D10: 1 | E10: 3
A11: Gesamtergebnis | B11: 18 | C11: 11 | D11: 16 | E11: 45

Sheet Ausleihen
A1: Gerätenummer | B1: Mitarbeiter-ID | C1: Ausgabe am | D1: Rückgabe am | E1: Gerätetyp | F1: Modell | G1: Kaufdatum | H1: Netto-Kaufpreis | I1: Standort
A2: G0035 | B2: 1009 | C2: 45421 | E2: =IFERROR(VLOOKUP(Ausleihen[[#This Row],[Gerätenummer]],Geraete!$A$2:$F$36,2,FALSE),"") -> Beamer | F2: =IFERROR(VLOOKUP(Ausleihen[[#This Row],[Gerätenummer]],Geraete!$A$2:$F$36,3,FALSE),"") -> BenQ MW550 | G2: =IFERROR(VLOOKUP(Ausleihen[[#This Row],[Gerätenummer]],Geraete!$A$2:$F$36,4,FALSE),"") -> 45294 | H2: =IFERROR(VLOOKUP(Ausleihen[[#This Row],[Gerätenummer]],Geraete!$A$2:$F$36,5,FALSE),"") -> 64454 | I2: =IFERROR(VLOOKUP(Ausleihen[[#This Row],[Gerätenummer]],Geraete!$A$2:$F$36,6,FALSE),"") -> Berlin
A3: G0021 | B3: 1008 | C3: 45930 | D3: 45935 | E3: =IFERROR(VLOOKUP(Ausleihen[[#This Row],[Gerätenummer]],Geraete!$A$2:$F$36,2,FALSE),"") -> Monitor | F3: =IFERROR(VLOOKUP(Ausleihen[[#This Row],[Gerätenummer]],Geraete!$A$2:$F$36,3,FALSE),"") -> Samsung Curved | G3: =IFERROR(VLOOKUP(Ausleihen[[#This Row],[Gerätenummer]],Geraete!$A$2:$F$36,4,FALSE),"") -> 44979 | H3: =IFERROR(VLOOKUP(Ausleihen[[#This Row],[Gerätenummer]],Geraete!$A$2:$F$36,5,FALSE),"") -> 113416 | I3: =IFERROR(VLOOKUP(Ausleihen[[#This Row],[Gerätenummer]],Geraete!$A$2:$F$36,6,FALSE),"") -> München
A4: G0024 | B4: 1005 | C4: 45743 | D4: 45868 | E4: =IFERROR(VLOOKUP(Ausleihen[[#This Row],[Gerätenummer]],Geraete!$A$2:$F$36,2,FALSE),"") -> Monitor | F4: =IFERROR(VLOOKUP(Ausleihen[[#This Row],[Gerätenummer]],Geraete!$A$2:$F$36,3,FALSE),"") -> Dell UltraSharp | G4: =IFERROR(VLOOKUP(Ausleihen[[#This Row],[Gerätenummer]],Geraete!$A$2:$F$36,4,FALSE),"") -> 44621 | H4: =IFERROR(VLOOKUP(Ausleihen[[#This Row],[Gerätenummer]],Geraete!$A$2:$F$36,5,FALSE),"") -> 75091 | I4: =IFERROR(VLOOKUP(Ausleihen[[#This Row],[Gerätenummer]],Geraete!$A$2:$F$36,6,FALSE),"") -> Berlin
A5: G0016 | B5: 1010 | C5: 45866 | E5: =IFERROR(VLOOKUP(Ausleihen[[#This Row],[Gerätenummer]],Geraete!$A$2:$F$36,2,FALSE),"") -> Drucker | F5: =IFERROR(VLOOKUP(Ausleihen[[#This Row],[Gerätenummer]],Geraete!$A$2:$F$36,3,FALSE),"") -> Canon Pixma | G5: =IFERROR(VLOOKUP(Ausleihen[[#This Row],[Gerätenummer]],Geraete!$A$2:$F$36,4,FALSE),"") -> 45015 | H5: =IFERROR(VLOOKUP(Ausleihen[[#This Row],[Gerätenummer]],Geraete!$A$2:$F$36,5,FALSE),"") -> 150106 | I5: =IFERROR(VLOOKUP(Ausleihen[[#This Row],[Gerätenummer]],Geraete!$A$2:$F$36,6,FALSE),"") -> Berlin
A6: G0006 | B6: 1012 | C6: 45808 | D6: 45818 | E6: =IFERROR(VLOOKUP(Ausleihen[[#This Row],[Gerätenummer]],Geraete!$A$2:$F$36,2,FALSE),"") -> Smartphone | F6: =IFERROR(VLOOKUP(Ausleihen[[#This Row],[Gerätenummer]],Geraete!$A$2:$F$36,3,FALSE),"") -> Samsung S21 | G6: =IFERROR(VLOOKUP(Ausleihen[[#This Row],[Gerätenummer]],Geraete!$A$2:$F$36,4,FALSE),"") -> 45292 | H6: =IFERROR(VLOOKUP(Ausleihen[[#This Row],[Gerätenummer]],Geraete!$A$2:$F$36,5,FALSE),"") -> 125796 | I6: =IFERROR(VLOOKUP(Ausleihen[[#This Row],[Gerätenummer]],Geraete!$A$2:$F$36,6,FALSE),"") -> München
A7: G0005 | B7: 1009 | C7: 45389 | E7: =IFERROR(VLOOKUP(Ausleihen[[#This Row],[Gerätenummer]],Geraete!$A$2:$F$36,2,FALSE),"") -> Drucker | F7: =IFERROR(VLOOKUP(Ausleihen[[#This Row],[Gerätenummer]],Geraete!$A$2:$F$36,3,FALSE),"") -> Canon Pixma | G7: =IFERROR(VLOOKUP(Ausleihen[[#This Row],[Gerätenummer]],Geraete!$A$2:$F$36,4,FALSE),"") -> 44503 | H7: =IFERROR(VLOOKUP(Ausleihen[[#This Row],[Gerätenummer]],Geraete!$A$2:$F$36,5,FALSE),"") -> 82323 | I7: =IFERROR(VLOOKUP(Ausleihen[[#This Row],[Gerätenummer]],Geraete!$A$2:$F$36,6,FALSE),"") -> Berlin
A8: G0009 | B8: 1011 | C8: 45850 | D8: 45853 | E8: =IFERROR(VLOOKUP(Ausleihen[[#This Row],[Gerätenummer]],Geraete!$A$2:$F$36,2,FALSE),"") -> Laptop | F8: =IFERROR(VLOOKUP(Ausleihen[[#This Row],[Gerätenummer]],Geraete!$A$2:$F$36,3,FALSE),"") -> Dell XPS | G8: =IFERROR(VLOOKUP(Ausleihen[[#This Row],[Gerätenummer]],Geraete!$A$2:$F$36,4,FALSE),"") -> 45026 | H8: =IFERROR(VLOOKUP(Ausleihen[[#This Row],[Gerätenummer]],Geraete!$A$2:$F$36,5,FALSE),"") -> 145802 | I8: =IFERROR(VLOOKUP(Ausleihen[[#This Row],[Gerätenummer]],Geraete!$A$2:$F$36,6,FALSE),"") -> München
A9: G0011 | B9: 1005 | C9: 45837 | D9: 45898 | E9: =IFERROR(VLOOKUP(Ausleihen[[#This Row],[Gerätenummer]],Geraete!$A$2:$F$36,2,FALSE),"") -> Drucker | F9: =IFERROR(VLOOKUP(Ausleihen[[#This Row],[Gerätenummer]],Geraete!$A$2:$F$36,3,FALSE),"") -> Brother HL | G9: =IFERROR(VLOOKUP(Ausleihen[[#This Row],[Gerätenummer]],Geraete!$A$2:$F$36,4,FALSE),"") -> 45909 | H9: =IFERROR(VLOOKUP(Ausleihen[[#This Row],[Gerätenummer]],Geraete!$A$2:$F$36,5,FALSE),"") -> 14171 | I9: =IFERROR(VLOOKUP(Ausleihen[[#This Row],[Gerätenummer]],Geraete!$A$2:$F$36,6,FALSE),"") -> München
A10: G0028 | B10: 1004 | C10: 45523 | E10: =IFERROR(VLOOKUP(Ausleihen[[#This Row],[Gerätenummer]],Geraete!$A$2:$F$36,2,FALSE),"") -> Beamer | F10: =IFERROR(VLOOKUP(Ausleihen[[#This Row],[Gerätenummer]],Geraete!$A$2:$F$36,3,FALSE),"") -> Epson EB | G10: =IFERROR(VLOOKUP(Ausleihen[[#This Row],[Gerätenummer]],Geraete!$A$2:$F$36,4,FALSE),"") -> 44945 | H10: =IFERROR(VLOOKUP(Ausleihen[[#This Row],[Gerätenummer]],Geraete!$A$2:$F$36,5,FALSE),"") -> 124658 | I10: =IFERROR(VLOOKUP(Ausleihen[[#This Row],[Gerätenummer]],Geraete!$A$2:$F$36,6,FALSE),"") -> Hamburg
A11: G0013 | B11: 1012 | C11: 45419 | D11: 45470 | E11: =IFERROR(VLOOKUP(Ausleihen[[#This Row],[Gerätenummer]],Geraete!$A$2:$F$36,2,FALSE),"") -> Drucker | F11: =IFERROR(VLOOKUP(Ausleihen[[#This Row],[Gerätenummer]],Geraete!$A$2:$F$36,3,FALSE),"") -> Canon Pixma | G11: =IFERROR(VLOOKUP(Ausleihen[[#This Row],[Gerätenummer]],Geraete!$A$2:$F$36,4,FALSE),"") -> 44332 | H11: =IFERROR(VLOOKUP(Ausleihen[[#This Row],[Gerätenummer]],Geraete!$A$2:$F$36,5,FALSE),"") -> 189865 | I11: =IFERROR(VLOOKUP(Ausleihen[[#This Row],[Gerätenummer]],Geraete!$A$2:$F$36,6,FALSE),"") -> Hamburg
A12: G0024 | B12: 1008 | C12: 45375 | E12: =IFERROR(VLOOKUP(Ausleihen[[#This Row],[Gerätenummer]],Geraete!$A$2:$F$36,2,FALSE),"") -> Monitor | F12: =IFERROR(VLOOKUP(Ausleihen[[#This Row],[Gerätenummer]],Geraete!$A$2:$F$36,3,FALSE),"") -> Dell UltraSharp | G12: =IFERROR(VLOOKUP(Ausleihen[[#This Row],[Gerätenummer]],Geraete!$A$2:$F$36,4,FALSE),"") -> 44621 | H12: =IFERROR(VLOOKUP(Ausleihen[[#This Row],[Gerätenummer]],Geraete!$A$2:$F$36,5,FALSE),"") -> 75091 | I12: =IFERROR(VLOOKUP(Ausleihen[[#This Row],[Gerätenummer]],Geraete!$A$2:$F$36,6,FALSE),"") -> Berlin
A13: G0029 | B13: 1002 | C13: 45921 | D13: 45934 | E13: =IFERROR(VLOOKUP(Ausleihen[[#This Row],[Gerätenummer]],Geraete!$A$2:$F$36,2,FALSE),"") -> Laptop | F13: =IFERROR(VLOOKUP(Ausleihen[[#This Row],[Gerätenummer]],Geraete!$A$2:$F$36,3,FALSE),"") -> Lenovo ThinkPad | G13: =IFERROR(VLOOKUP(Ausleihen[[#This Row],[Gerätenummer]],Geraete!$A$2:$F$36,4,FALSE),"") -> 44337 | H13: =IFERROR(VLOOKUP(Ausleihen[[#This Row],[Gerätenummer]],Geraete!$A$2:$F$36,5,FALSE),"") -> 155315 | I13: =IFERROR(VLOOKUP(Ausleihen[[#This Row],[Gerätenummer]],Geraete!$A$2:$F$36,6,FALSE),"") -> Hamburg
A14: G0005 | B14: 1006 | C14: 45892 | D14: 45922 | E14: =IFERROR(VLOOKUP(Ausleihen[[#This Row],[Gerätenummer]],Geraete!$A$2:$F$36,2,FALSE),"") -> Drucker | F14: =IFERROR(VLOOKUP(Ausleihen[[#This Row],[Gerätenummer]],Geraete!$A$2:$F$36,3,FALSE),"") -> Canon Pixma | G14: =IFERROR(VLOOKUP(Ausleihen[[#This Row],[Gerätenummer]],Geraete!$A$2:$F$36,4,FALSE),"") -> 44503 | H14: =IFERROR(VLOOKUP(Ausleihen[[#This Row],[Gerätenummer]],Geraete!$A$2:$F$36,5,FALSE),"") -> 82323 | I14: =IFERROR(VLOOKUP(Ausleihen[[#This Row],[Gerätenummer]],Geraete!$A$2:$F$36,6,FALSE),"") -> Berlin
A15: G0015 | B15: 1010 | C15: 45377 | D15: 45886 | E15: =IFERROR(VLOOKUP(Ausleihen[[#This Row],[Gerätenummer]],Geraete!$A$2:$F$36,2,FALSE),"") -> Smartphone | F15: =IFERROR(VLOOKUP(Ausleihen[[#This Row],[Gerätenummer]],Geraete!$A$2:$F$36,3,FALSE),"") -> iPhone 13 | G15: =IFERROR(VLOOKUP(Ausleihen[[#This Row],[Gerätenummer]],Geraete!$A$2:$F$36,4,FALSE),"") -> 44824 | H15: =IFERROR(VLOOKUP(Ausleihen[[#This Row],[Gerätenummer]],Geraete!$A$2:$F$36,5,FALSE),"") -> 66144 | I15: =IFERROR(VLOOKUP(Ausleihen[[#This Row],[Gerätenummer]],Geraete!$A$2:$F$36,6,FALSE),"") -> München
A16: G0005 | B16: 1012 | C16: 45599 | E16: =IFERROR(VLOOKUP(Ausleihen[[#This Row],[Gerätenummer]],Geraete!$A$2:$F$36,2,FALSE),"") -> Drucker | F16: =IFERROR(VLOOKUP(Ausleihen[[#This Row],[Gerätenummer]],Geraete!$A$2:$F$36,3,FALSE),"") -> Canon Pixma | G16: =IFERROR(VLOOKUP(Ausleihen[[#This Row],[Gerätenummer]],Geraete!$A$2:$F$36,4,FALSE),"") -> 44503 | H16: =IFERROR(VLOOKUP(Ausleihen[[#This Row],[Gerätenummer]],Geraete!$A$2:$F$36,5,FALSE),"") -> 82323 | I16: =IFERROR(VLOOKUP(Ausleihen[[#This Row],[Gerätenummer]],Geraete!$A$2:$F$36,6,FALSE),"") -> Berlin
A17: G0015 | B17: 1002 | C17: 45519 | E17: =IFERROR(VLOOKUP(Ausleihen[[#This Row],[Gerätenummer]],Geraete!$A$2:$F$36,2,FALSE),"") -> Smartphone | F17: =IFERROR(VLOOKUP(Ausleihen[[#This Row],[Gerätenummer]],Geraete!$A$2:$F$36,3,FALSE),"") -> iPhone 13 | G17: =IFERROR(VLOOKUP(Ausleihen[[#This Row],[Gerätenummer]],Geraete!$A$2:$F$36,4,FALSE),"") -> 44824 | H17: =IFERROR(VLOOKUP(Ausleihen[[#This Row],[Gerätenummer]],Geraete!$A$2:$F$36,5,FALSE),"") -> 66144 | I17: =IFERROR(VLOOKUP(Ausleihen[[#This Row],[Gerätenummer]],Geraete!$A$2:$F$36,6,FALSE),"") -> München
A18: G0022 | B18: 1002 | C18: 45899 | D18: 45930 | E18: =IFERROR(VLOOKUP(Ausleihen[[#This Row],[Gerätenummer]],Geraete!$A$2:$F$36,2,FALSE),"") -> Tablet | F18: =IFERROR(VLOOKUP(Ausleihen[[#This Row],[Gerätenummer]],Geraete!$A$2:$F$36,3,FALSE),"") -> iPad | G18: =IFERROR(VLOOKUP(Ausleihen[[#This Row],[Gerätenummer]],Geraete!$A$2:$F$36,4,FALSE),"") -> 45524 | H18: =IFERROR(VLOOKUP(Ausleihen[[#This Row],[Gerätenummer]],Geraete!$A$2:$F$36,5,FALSE),"") -> 159198 | I18: =IFERROR(VLOOKUP(Ausleihen[[#This Row],[Gerätenummer]],Geraete!$A$2:$F$36,6,FALSE),"") -> Hamburg
A19: G0018 | B19: 1011 | C19: 45568 | D19: 45623 | E19: =IFERROR(VLOOKUP(Ausleihen[[#This Row],[Gerätenummer]],Geraete!$A$2:$F$36,2,FALSE),"") -> Tablet | F19: =IFERROR(VLOOKUP(Ausleihen[[#This Row],[Gerätenummer]],Geraete!$A$2:$F$36,3,FALSE),"") -> iPad | G19: =IFERROR(VLOOKUP(Ausleihen[[#This Row],[Gerätenummer]],Geraete!$A$2:$F$36,4,FALSE),"") -> 44839 | H19: =IFERROR(VLOOKUP(Ausleihen[[#This Row],[Gerätenummer]],Geraete!$A$2:$F$36,5,FALSE),"") -> 168807 | I19: =IFERROR(VLOOKUP(Ausleihen[[#This Row],[Gerätenummer]],Geraete!$A$2:$F$36,6,FALSE),"") -> München
A20: G0035 | B20: 1003 | C20: 45417 | E20: =IFERROR(VLOOKUP(Ausleihen[[#This Row],[Gerätenummer]],Geraete!$A$2:$F$36,2,FALSE),"") -> Beamer | F20: =IFERROR(VLOOKUP(Ausleihen[[#This Row],[Gerätenummer]],Geraete!$A$2:$F$36,3,FALSE),"") -> BenQ MW550 | G20: =IFERROR(VLOOKUP(Ausleihen[[#This Row],[Gerätenummer]],Geraete!$A$2:$F$36,4,FALSE),"") -> 45294 | H20: =IFERROR(VLOOKUP(Ausleihen[[#This Row],[Gerätenummer]],Geraete!$A$2:$F$36,5,FALSE),"") -> 64454 | I20: =IFERROR(VLOOKUP(Ausleihen[[#This Row],[Gerätenummer]],Geraete!$A$2:$F$36,6,FALSE),"") -> Berlin
A21: G0031 | B21: 1004 | C21: 45320 | E21: =IFERROR(VLOOKUP(Ausleihen[[#This Row],[Gerätenummer]],Geraete!$A$2:$F$36,2,FALSE),"") -> Laptop | F21: =IFERROR(VLOOKUP(Ausleihen[[#This Row],[Gerätenummer]],Geraete!$A$2:$F$36,3,FALSE),"") -> HP EliteBook | G21: =IFERROR(VLOOKUP(Ausleihen[[#This Row],[Gerätenummer]],Geraete!$A$2:$F$36,4,FALSE),"") -> 45775 | H21: =IFERROR(VLOOKUP(Ausleihen[[#This Row],[Gerätenummer]],Geraete!$A$2:$F$36,5,FALSE),"") -> 109562 | I21: =IFERROR(VLOOKUP(Ausleihen[[#This Row],[Gerätenummer]],Geraete!$A$2:$F$36,6,FALSE),"") -> München
A22: G0027 | B22: 1004 | C22: 45403 | D22: 45839 | E22: =IFERROR(VLOOKUP(Ausleihen[[#This Row],[Gerätenummer]],Geraete!$A$2:$F$36,2,FALSE),"") -> Monitor | F22: =IFERROR(VLOOKUP(Ausleihen[[#This Row],[Gerätenummer]],Geraete!$A$2:$F$36,3,FALSE),"") -> Samsung Curved | G22: =IFERROR(VLOOKUP(Ausleihen[[#This Row],[Gerätenummer]],Geraete!$A$2:$F$36,4,FALSE),"") -> 44766 | H22: =IFERROR(VLOOKUP(Ausleihen[[#This Row],[Gerätenummer]],Geraete!$A$2:$F$36,5,FALSE),"") -> 50164 | I22: =IFERROR(VLOOKUP(Ausleihen[[#This Row],[Gerätenummer]],Geraete!$A$2:$F$36,6,FALSE),"") -> München
A23: G0028 | B23: 1006 | C23: 45630 | D23: 45732 | E23: =IFERROR(VLOOKUP(Ausleihen[[#This Row],[Gerätenummer]],Geraete!$A$2:$F$36,2,FALSE),"") -> Beamer | F23: =IFERROR(VLOOKUP(Ausleihen[[#This Row],[Gerätenummer]],Geraete!$A$2:$F$36,3,FALSE),"") -> Epson EB | G23: =IFERROR(VLOOKUP(Ausleihen[[#This Row],[Gerätenummer]],Geraete!$A$2:$F$36,4,FALSE),"") -> 44945 | H23: =IFERROR(VLOOKUP(Ausleihen[[#This Row],[Gerätenummer]],Geraete!$A$2:$F$36,5,FALSE),"") -> 124658 | I23: =IFERROR(VLOOKUP(Ausleihen[[#This Row],[Gerätenummer]],Geraete!$A$2:$F$36,6,FALSE),"") -> Hamburg
A24: G0030 | B24: 1012 | C24: 45792 | D24: 45905 | E24: =IFERROR(VLOOKUP(Ausleihen[[#This Row],[Gerätenummer]],Geraete!$A$2:$F$36,2,FALSE),"") -> Beamer | F24: =IFERROR(VLOOKUP(Ausleihen[[#This Row],[Gerätenummer]],Geraete!$A$2:$F$36,3,FALSE),"") -> Epson EB | G24: =IFERROR(VLOOKUP(Ausleihen[[#This Row],[Gerätenummer]],Geraete!$A$2:$F$36,4,FALSE),"") -> 44647 | H24: =IFERROR(VLOOKUP(Ausleihen[[#This Row],[Gerätenummer]],Geraete!$A$2:$F$36,5,FALSE),"") -> 162976 | I24: =IFERROR(VLOOKUP(Ausleihen[[#This Row],[Gerätenummer]],Geraete!$A$2:$F$36,6,FALSE),"") -> München
A25: G0007 | B25: 1001 | C25: 45544 | D25: 45854 | E25: =IFERROR(VLOOKUP(Ausleihen[[#This Row],[Gerätenummer]],Geraete!$A$2:$F$36,2,FALSE),"") -> Laptop | F25: =IFERROR(VLOOKUP(Ausleihen[[#This Row],[Gerätenummer]],Geraete!$A$2:$F$36,3,FALSE),"") -> Lenovo ThinkPad | G25: =IFERROR(VLOOKUP(Ausleihen[[#This Row],[Gerätenummer]],Geraete!$A$2:$F$36,4,FALSE),"") -> 44360 | H25: =IFERROR(VLOOKUP(Ausleihen[[#This Row],[Gerätenummer]],Geraete!$A$2:$F$36,5,FALSE),"") -> 86909 | I25: =IFERROR(VLOOKUP(Ausleihen[[#This Row],[Gerätenummer]],Geraete!$A$2:$F$36,6,FALSE),"") -> Hamburg
A26: G0022 | B26: 1002 | C26: 45493 | D26: 45663 | E26: =IFERROR(VLOOKUP(Ausleihen[[#This Row],[Gerätenummer]],Geraete!$A$2:$F$36,2,FALSE),"") -> Tablet | F26: =IFERROR(VLOOKUP(Ausleihen[[#This Row],[Gerätenummer]],Geraete!$A$2:$F$36,3,FALSE),"") -> iPad | G26: =IFERROR(VLOOKUP(Ausleihen[[#This Row],[Gerätenummer]],Geraete!$A$2:$F$36,4,FALSE),"") -> 45524 | H26: =IFERROR(VLOOKUP(Ausleihen[[#This Row],[Gerätenummer]],Geraete!$A$2:$F$36,5,FALSE),"") -> 159198 | I26: =IFERROR(VLOOKUP(Ausleihen[[#This Row],[Gerätenummer]],Geraete!$A$2:$F$36,6,FALSE),"") -> Hamburg
A27: G0013 | B27: 1009 | C27: 45319 | D27: 45714 | E27: =IFERROR(VLOOKUP(Ausleihen[[#This Row],[Gerätenummer]],Geraete!$A$2:$F$36,2,FALSE),"") -> Drucker | F27: =IFERROR(VLOOKUP(Ausleihen[[#This Row],[Gerätenummer]],Geraete!$A$2:$F$36,3,FALSE),"") -> Canon Pixma | G27: =IFERROR(VLOOKUP(Ausleihen[[#This Row],[Gerätenummer]],Geraete!$A$2:$F$36,4,FALSE),"") -> 44332 | H27: =IFERROR(VLOOKUP(Ausleihen[[#This Row],[Gerätenummer]],Geraete!$A$2:$F$36,5,FALSE),"") -> 189865 | I27: =IFERROR(VLOOKUP(Ausleihen[[#This Row],[Gerätenummer]],Geraete!$A$2:$F$36,6,FALSE),"") -> Hamburg
A28: G0028 | B28: 1003 | C28: 45595 | D28: 45630 | E28: =IFERROR(VLOOKUP(Ausleihen[[#This Row],[Gerätenummer]],Geraete!$A$2:$F$36,2,FALSE),"") -> Beamer | F28: =IFERROR(VLOOKUP(Ausleihen[[#This Row],[Gerätenummer]],Geraete!$A$2:$F$36,3,FALSE),"") -> Epson EB | G28: =IFERROR(VLOOKUP(Ausleihen[[#This Row],[Gerätenummer]],Geraete!$A$2:$F$36,4,FALSE),"") -> 44945 | H28: =IFERROR(VLOOKUP(Ausleihen[[#This Row],[Gerätenummer]],Geraete!$A$2:$F$36,5,FALSE),"") -> 124658 | I28: =IFERROR(VLOOKUP(Ausleihen[[#This Row],[Gerätenummer]],Geraete!$A$2:$F$36,6,FALSE),"") -> Hamburg
A29: G0016 | B29: 1002 | C29: 45799 | D29: 45808 | E29: =IFERROR(VLOOKUP(Ausleihen[[#This Row],[Gerätenummer]],Geraete!$A$2:$F$36,2,FALSE),"") -> Drucker | F29: =IFERROR(VLOOKUP(Ausleihen[[#This Row],[Gerätenummer]],Geraete!$A$2:$F$36,3,FALSE),"") -> Canon Pixma | G29: =IFERROR(VLOOKUP(Ausleihen[[#This Row],[Gerätenummer]],Geraete!$A$2:$F$36,4,FALSE),"") -> 45015 | H29: =IFERROR(VLOOKUP(Ausleihen[[#This Row],[Gerätenummer]],Geraete!$A$2:$F$36,5,FALSE),"") -> 150106 | I29: =IFERROR(VLOOKUP(Ausleihen[[#This Row],[Gerätenummer]],Geraete!$A$2:$F$36,6,FALSE),"") -> Berlin
A30: G0007 | B30: 1001 | C30: 45880 | E30: =IFERROR(VLOOKUP(Ausleihen[[#This Row],[Gerätenummer]],Geraete!$A$2:$F$36,2,FALSE),"") -> Laptop | F30: =IFERROR(VLOOKUP(Ausleihen[[#This Row],[Gerätenummer]],Geraete!$A$2:$F$36,3,FALSE),"") -> Lenovo ThinkPad | G30: =IFERROR(VLOOKUP(Ausleihen[[#This Row],[Gerätenummer]],Geraete!$A$2:$F$36,4,FALSE),"") -> 44360 | H30: =IFERROR(VLOOKUP(Ausleihen[[#This Row],[Gerätenummer]],Geraete!$A$2:$F$36,5,FALSE),"") -> 86909 | I30: =IFERROR(VLOOKUP(Ausleihen[[#This Row],[Gerätenummer]],Geraete!$A$2:$F$36,6,FALSE),"") -> Hamburg
A31: G0035 | B31: 1001 | C31: 45297 | E31: =IFERROR(VLOOKUP(Ausleihen[[#This Row],[Gerätenummer]],Geraete!$A$2:$F$36,2,FALSE),"") -> Beamer | F31: =IFERROR(VLOOKUP(Ausleihen[[#This Row],[Gerätenummer]],Geraete!$A$2:$F$36,3,FALSE),"") -> BenQ MW550 | G31: =IFERROR(VLOOKUP(Ausleihen[[#This Row],[Gerätenummer]],Geraete!$A$2:$F$36,4,FALSE),"") -> 45294 | H31: =IFERROR(VLOOKUP(Ausleihen[[#This Row],[Gerätenummer]],Geraete!$A$2:$F$36,5,FALSE),"") -> 64454 | I31: =IFERROR(VLOOKUP(Ausleihen[[#This Row],[Gerätenummer]],Geraete!$A$2:$F$36,6,FALSE),"") -> Berlin
A32: G0016 | B32: 1003 | C32: 45330 | D32: 45817 | E32: =IFERROR(VLOOKUP(Ausleihen[[#This Row],[Gerätenummer]],Geraete!$A$2:$F$36,2,FALSE),"") -> Drucker | F32: =IFERROR(VLOOKUP(Ausleihen[[#This Row],[Gerätenummer]],Geraete!$A$2:$F$36,3,FALSE),"") -> Canon Pixma | G32: =IFERROR(VLOOKUP(Ausleihen[[#This Row],[Gerätenummer]],Geraete!$A$2:$F$36,4,FALSE),"") -> 45015 | H32: =IFERROR(VLOOKUP(Ausleihen[[#This Row],[Gerätenummer]],Geraete!$A$2:$F$36,5,FALSE),"") -> 150106 | I32: =IFERROR(VLOOKUP(Ausleihen[[#This Row],[Gerätenummer]],Geraete!$A$2:$F$36,6,FALSE),"") -> Berlin
A33: G0031 | B33: 1004 | C33: 45336 | E33: =IFERROR(VLOOKUP(Ausleihen[[#This Row],[Gerätenummer]],Geraete!$A$2:$F$36,2,FALSE),"") -> Laptop | F33: =IFERROR(VLOOKUP(Ausleihen[[#This Row],[Gerätenummer]],Geraete!$A$2:$F$36,3,FALSE),"") -> HP EliteBook | G33: =IFERROR(VLOOKUP(Ausleihen[[#This Row],[Gerätenummer]],Geraete!$A$2:$F$36,4,FALSE),"") -> 45775 | H33: =IFERROR(VLOOKUP(Ausleihen[[#This Row],[Gerätenummer]],Geraete!$A$2:$F$36,5,FALSE),"") -> 109562 | I33: =IFERROR(VLOOKUP(Ausleihen[[#This Row],[Gerätenummer]],Geraete!$A$2:$F$36,6,FALSE),"") -> München
A34: G0004 | B34: 1003 | C34: 45827 | D34: 45908 | E34: =IFERROR(VLOOKUP(Ausleihen[[#This Row],[Gerätenummer]],Geraete!$A$2:$F$36,2,FALSE),"") -> Laptop | F34: =IFERROR(VLOOKUP(Ausleihen[[#This Row],[Gerätenummer]],Geraete!$A$2:$F$36,3,FALSE),"") -> Dell XPS | G34: =IFERROR(VLOOKUP(Ausleihen[[#This Row],[Gerätenummer]],Geraete!$A$2:$F$36,4,FALSE),"") -> 45782 | H34: =IFERROR(VLOOKUP(Ausleihen[[#This Row],[Gerätenummer]],Geraete!$A$2:$F$36,5,FALSE),"") -> 100788 | I34: =IFERROR(VLOOKUP(Ausleihen[[#This Row],[Gerätenummer]],Geraete!$A$2:$F$36,6,FALSE),"") -> München
A35: G0025 | B35: 1005 | C35: 45675 | E35: =IFERROR(VLOOKUP(Ausleihen[[#This Row],[Gerätenummer]],Geraete!$A$2:$F$36,2,FALSE),"") -> Beamer | F35: =IFERROR(VLOOKUP(Ausleihen[[#This Row],[Gerätenummer]],Geraete!$A$2:$F$36,3,FALSE),"") -> Epson EB | G35: =IFERROR(VLOOKUP(Ausleihen[[#This Row],[Gerätenummer]],Geraete!$A$2:$F$36,4,FALSE),"") -> 45266 | H35: =IFERROR(VLOOKUP(Ausleihen[[#This Row],[Gerätenummer]],Geraete!$A$2:$F$36,5,FALSE),"") -> 54546 | I35: =IFERROR(VLOOKUP(Ausleihen[[#This Row],[Gerätenummer]],Geraete!$A$2:$F$36,6,FALSE),"") -> Berlin
A36: G0030 | B36: 1005 | C36: 45261 | D36: 45559 | E36: =IFERROR(VLOOKUP(Ausleihen[[#This Row],[Gerätenummer]],Geraete!$A$2:$F$36,2,FALSE),"") -> Beamer | F36: =IFERROR(VLOOKUP(Ausleihen[[#This Row],[Gerätenummer]],Geraete!$A$2:$F$36,3,FALSE),"") -> Epson EB | G36: =IFERROR(VLOOKUP(Ausleihen[[#This Row],[Gerätenummer]],Geraete!$A$2:$F$36,4,FALSE),"") -> 44647 | H36: =IFERROR(VLOOKUP(Ausleihen[[#This Row],[Gerätenummer]],Geraete!$A$2:$F$36,5,FALSE),"") -> 162976 | I36: =IFERROR(VLOOKUP(Ausleihen[[#This Row],[Gerätenummer]],Geraete!$A$2:$F$36,6,FALSE),"") -> München
A37: G0032 | B37: 1003 | C37: 45508 | D37: 45871 | E37: =IFERROR(VLOOKUP(Ausleihen[[#This Row],[Gerätenummer]],Geraete!$A$2:$F$36,2,FALSE),"") -> Laptop | F37: =IFERROR(VLOOKUP(Ausleihen[[#This Row],[Gerätenummer]],Geraete!$A$2:$F$36,3,FALSE),"") -> Lenovo ThinkPad | G37: =IFERROR(VLOOKUP(Ausleihen[[#This Row],[Gerätenummer]],Geraete!$A$2:$F$36,4,FALSE),"") -> 44876 | H37: =IFERROR(VLOOKUP(Ausleihen[[#This Row],[Gerätenummer]],Geraete!$A$2:$F$36,5,FALSE),"") -> 180136 | I37: =IFERROR(VLOOKUP(Ausleihen[[#This Row],[Gerätenummer]],Geraete!$A$2:$F$36,6,FALSE),"") -> München
A38: G0014 | B38: 1001 | C38: 45622 | D38: 45719 | E38: =IFERROR(VLOOKUP(Ausleihen[[#This Row],[Gerätenummer]],Geraete!$A$2:$F$36,2,FALSE),"") -> Laptop | F38: =IFERROR(VLOOKUP(Ausleihen[[#This Row],[Gerätenummer]],Geraete!$A$2:$F$36,3,FALSE),"") -> Lenovo ThinkPad | G38: =IFERROR(VLOOKUP(Ausleihen[[#This Row],[Gerätenummer]],Geraete!$A$2:$F$36,4,FALSE),"") -> 44258 | H38: =IFERROR(VLOOKUP(Ausleihen[[#This Row],[Gerätenummer]],Geraete!$A$2:$F$36,5,FALSE),"") -> 141597 | I38: =IFERROR(VLOOKUP(Ausleihen[[#This Row],[Gerätenummer]],Geraete!$A$2:$F$36,6,FALSE),"") -> Hamburg
A39: G0035 | B39: 1001 | C39: 45641 | E39: =IFERROR(VLOOKUP(Ausleihen[[#This Row],[Gerätenummer]],Geraete!$A$2:$F$36,2,FALSE),"") -> Beamer | F39: =IFERROR(VLOOKUP(Ausleihen[[#This Row],[Gerätenummer]],Geraete!$A$2:$F$36,3,FALSE),"") -> BenQ MW550 | G39: =IFERROR(VLOOKUP(Ausleihen[[#This Row],[Gerätenummer]],Geraete!$A$2:$F$36,4,FALSE),"") -> 45294 | H39: =IFERROR(VLOOKUP(Ausleihen[[#This Row],[Gerätenummer]],Geraete!$A$2:$F$36,5,FALSE),"") -> 64454 | I39: =IFERROR(VLOOKUP(Ausleihen[[#This Row],[Gerätenummer]],Geraete!$A$2:$F$36,6,FALSE),"") -> Berlin
A40: G0004 | B40: 1001 | C40: 45880 | D40: 45881 | E40: =IFERROR(VLOOKUP(Ausleihen[[#This Row],[Gerätenummer]],Geraete!$A$2:$F$36,2,FALSE),"") -> Laptop | F40: =IFERROR(VLOOKUP(Ausleihen[[#This Row],[Gerätenummer]],Geraete!$A$2:$F$36,3,FALSE),"") -> Dell XPS | G40: =IFERROR(VLOOKUP(Ausleihen[[#This Row],[Gerätenummer]],Geraete!$A$2:$F$36,4,FALSE),"") -> 45782 | H40: =IFERROR(VLOOKUP(Ausleihen[[#This Row],[Gerätenummer]],Geraete!$A$2:$F$36,5,FALSE),"") -> 100788 | I40: =IFERROR(VLOOKUP(Ausleihen[[#This Row],[Gerätenummer]],Geraete!$A$2:$F$36,6,FALSE),"") -> München
...

Sheet Tabelle6
A3: Summe von Netto-Kaufpreis
A4: 4190571

Sheet Tabelle7
A1: Rückgabe am | B1: (Mehrere Elemente)
A2: Gerätetyp | B2: Laptop
A4: Summe von Netto-Kaufpreis
A5: 920109

Sheet Geraete
A1: Gerätenummer | B1: Gerätetyp | C1: Modell | D1: Kaufdatum | E1: Netto-Kaufpreis | F1: Standort | G1: Mitarbeiter-ID | H1: Ausgabe am | I1: Rückgabe am
A2: G0001 | B2: Tablet | C2: Galaxy Tab | D2: 44937 | E2: 134283 | F2: Berlin | G2: =IFERROR(VLOOKUP(Geraete__3[[#This Row],[Gerätenummer]],Ausleihen!$A$2:$D$46,2,FALSE),"") | H2: =IFERROR(VLOOKUP(Geraete__3[[#This Row],[Gerätenummer]],Ausleihen!$A$2:$D$46,3,FALSE),"") | I2: =IFERROR(VLOOKUP(Geraete__3[[#This Row],[Gerätenummer]],Ausleihen!$A$2:$D$46,4,FALSE),"") | K2: {=SUM(IF(D2:D98<>"",VLOOKUP(A2:A98,Geraete!A$2:E$37,5,FALSE),0))} -> 4190571
A3: G0002 | B3: Tablet | C3: Surface Go | D3: 44250 | E3: 107618 | F3: München | G3: =IFERROR(VLOOKUP(Geraete__3[[#This Row],[Gerätenummer]],Ausleihen!$A$2:$D$46,2,FALSE),"") | H3: =IFERROR(VLOOKUP(Geraete__3[[#This Row],[Gerätenummer]],Ausleihen!$A$2:$D$46,3,FALSE),"") | I3: =IFERROR(VLOOKUP(Geraete__3[[#This Row],[Gerätenummer]],Ausleihen!$A$2:$D$46,4,FALSE),"")
A4: G0003 | B4: Tablet | C4: iPad | D4: 45543 | E4: 193154 | F4: München | G4: =IFERROR(VLOOKUP(Geraete__3[[#This Row],[Gerätenummer]],Ausleihen!$A$2:$D$46,2,FALSE),"") | H4: =IFERROR(VLOOKUP(Geraete__3[[#This Row],[Gerätenummer]],Ausleihen!$A$2:$D$46,3,FALSE),"") | I4: =IFERROR(VLOOKUP(Geraete__3[[#This Row],[Gerätenummer]],Ausleihen!$A$2:$D$46,4,FALSE),"")
A5: G0004 | B5: Laptop | C5: Dell XPS | D5: 45782 | E5: 100788 | F5: München | G5: =IFERROR(VLOOKUP(Geraete__3[[#This Row],[Gerätenummer]],Ausleihen!$A$2:$D$46,2,FALSE),"") -> 1003 | H5: =IFERROR(VLOOKUP(Geraete__3[[#This Row],[Gerätenummer]],Ausleihen!$A$2:$D$46,3,FALSE),"") -> 45827 | I5: =IFERROR(VLOOKUP(Geraete__3[[#This Row],[Gerätenummer]],Ausleihen!$A$2:$D$46,4,FALSE),"") -> 45908
A6: G0005 | B6: Drucker | C6: Canon Pixma | D6: 44503 | E6: 82323 | F6: Berlin | G6: =IFERROR(VLOOKUP(Geraete__3[[#This Row],[Gerätenummer]],Ausleihen!$A$2:$D$46,2,FALSE),"") -> 1009 | H6: =IFERROR(VLOOKUP(Geraete__3[[#This Row],[Gerätenummer]],Ausleihen!$A$2:$D$46,3,FALSE),"") -> 45389 | I6: =IFERROR(VLOOKUP(Geraete__3[[#This Row],[Gerätenummer]],Ausleihen!$A$2:$D$46,4,FALSE),"") -> 0
A7: G0006 | B7: Smartphone | C7: Samsung S21 | D7: 45292 | E7: 125796 | F7: München | G7: =IFERROR(VLOOKUP(Geraete__3[[#This Row],[Gerätenummer]],Ausleihen!$A$2:$D$46,2,FALSE),"") -> 1012 | H7: =IFERROR(VLOOKUP(Geraete__3[[#This Row],[Gerätenummer]],Ausleihen!$A$2:$D$46,3,FALSE),"") -> 45808 | I7: =IFERROR(VLOOKUP(Geraete__3[[#This Row],[Gerätenummer]],Ausleihen!$A$2:$D$46,4,FALSE),"") -> 45818
A8: G0007 | B8: Laptop | C8: Lenovo ThinkPad | D8: 44360 | E8: 86909 | F8: Hamburg | G8: =IFERROR(VLOOKUP(Geraete__3[[#This Row],[Gerätenummer]],Ausleihen!$A$2:$D$46,2,FALSE),"") -> 1001 | H8: =IFERROR(VLOOKUP(Geraete__3[[#This Row],[Gerätenummer]],Ausleihen!$A$2:$D$46,3,FALSE),"") -> 45544 | I8: =IFERROR(VLOOKUP(Geraete__3[[#This Row],[Gerätenummer]],Ausleihen!$A$2:$D$46,4,FALSE),"") -> 45854
A9: G0008 | B9: Beamer | C9: Epson EB | D9: 45831 | E9: 132376 | F9: Hamburg | G9: =IFERROR(VLOOKUP(Geraete__3[[#This Row],[Gerätenummer]],Ausleihen!$A$2:$D$46,2,FALSE),"") | H9: =IFERROR(VLOOKUP(Geraete__3[[#This Row],[Gerätenummer]],Ausleihen!$A$2:$D$46,3,FALSE),"") | I9: =IFERROR(VLOOKUP(Geraete__3[[#This Row],[Gerätenummer]],Ausleihen!$A$2:$D$46,4,FALSE),"")
A10: G0009 | B10: Laptop | C10: Dell XPS | D10: 45026 | E10: 145802 | F10: München | G10: =IFERROR(VLOOKUP(Geraete__3[[#This Row],[Gerätenummer]],Ausleihen!$A$2:$D$46,2,FALSE),"") -> 1011 | H10: =IFERROR(VLOOKUP(Geraete__3[[#This Row],[Gerätenummer]],Ausleihen!$A$2:$D$46,3,FALSE),"") -> 45850 | I10: =IFERROR(VLOOKUP(Geraete__3[[#This Row],[Gerätenummer]],Ausleihen!$A$2:$D$46,4,FALSE),"") -> 45853
A11: G0010 | B11: Laptop | C11: Dell XPS | D11: 45239 | E11: 178637 | F11: München | G11: =IFERROR(VLOOKUP(Geraete__3[[#This Row],[Gerätenummer]],Ausleihen!$A$2:$D$46,2,FALSE),"") | H11: =IFERROR(VLOOKUP(Geraete__3[[#This Row],[Gerätenummer]],Ausleihen!$A$2:$D$46,3,FALSE),"") | I11: =IFERROR(VLOOKUP(Geraete__3[[#This Row],[Gerätenummer]],Ausleihen!$A$2:$D$46,4,FALSE),"")
A12: G0011 | B12: Drucker | C12: Brother HL | D12: 45909 | E12: 14171 | F12: München | G12: =IFERROR(VLOOKUP(Geraete__3[[#This Row],[Gerätenummer]],Ausleihen!$A$2:$D$46,2,FALSE),"") -> 1005 | H12: =IFERROR(VLOOKUP(Geraete__3[[#This Row],[Gerätenummer]],Ausleihen!$A$2:$D$46,3,FALSE),"") -> 45837 | I12: =IFERROR(VLOOKUP(Geraete__3[[#This Row],[Gerätenummer]],Ausleihen!$A$2:$D$46,4,FALSE),"") -> 45898
A13: G0012 | B13: Tablet | C13: Galaxy Tab | D13: 44713 | E13: 96843 | F13: Hamburg | G13: =IFERROR(VLOOKUP(Geraete__3[[#This Row],[Gerätenummer]],Ausleihen!$A$2:$D$46,2,FALSE),"") | H13: =IFERROR(VLOOKUP(Geraete__3[[#This Row],[Gerätenummer]],Ausleihen!$A$2:$D$46,3,FALSE),"") | I13: =IFERROR(VLOOKUP(Geraete__3[[#This Row],[Gerätenummer]],Ausleihen!$A$2:$D$46,4,FALSE),"")
A14: G0013 | B14: Drucker | C14: Canon Pixma | D14: 44332 | E14: 189865 | F14: Hamburg | G14: =IFERROR(VLOOKUP(Geraete__3[[#This Row],[Gerätenummer]],Ausleihen!$A$2:$D$46,2,FALSE),"") -> 1012 | H14: =IFERROR(VLOOKUP(Geraete__3[[#This Row],[Gerätenummer]],Ausleihen!$A$2:$D$46,3,FALSE),"") -> 45419 | I14: =IFERROR(VLOOKUP(Geraete__3[[#This Row],[Gerätenummer]],Ausleihen!$A$2:$D$46,4,FALSE),"") -> 45470
... A36: G0035 | B36: Beamer | C36: BenQ MW550 | D36: 45294 | E36: 64454 | F36: Berlin | G36: =IFERROR(VLOOKUP(Geraete__3[[#This Row],[Gerätenummer]],Ausleihen!$A$2:$D$46,2,FALSE),"") -> 1009 | H36: =IFERROR(VLOOKUP(Geraete__3[[#This Row],[Gerätenummer]],Ausleihen!$A$2:$D$46,3,FALSE),"") -> 45421 | I36: =IFERROR(VLOOKUP(Geraete__3[[#This Row],[Gerätenummer]],Ausleihen!$A$2:$D$46,4,FALSE),"") -> 0
G37: =IFERROR(VLOOKUP(Geraete__3[[#This Row],[Gerätenummer]],Ausleihen!$A$2:$D$46,2,FALSE),"") | H37: =IFERROR(VLOOKUP(Geraete__3[[#This Row],[Gerätenummer]],Ausleihen!$A$2:$D$46,3,FALSE),"") | I37: =IFERROR(VLOOKUP(Geraete__3[[#This Row],[Gerätenummer]],Ausleihen!$A$2:$D$46,4,FALSE),"")

Sheet Mitarbeiter
A1: Mitarbeiter-ID | B1: Name | C1: Abteilung | D1: Standort
A2: 1001 | B2: Aleksandr Weinhage | C2: IT | D2: Berlin
A3: 1002 | B3: Eleni Hauffer | C3: IT | D3: Berlin
A4: 1003 | B4: Paul Dobes-Stiffel | C4: Produktion | D4: Hamburg
A5: 1004 | B5: Klemens Löffler | C5: Vertrieb | D5: Hamburg
A6: 1005 | B6: Alexandre Davids | C6: Vertrieb | D6: Berlin
A7: 1006 | B7: Eric Patberg B.Sc. | C7: Vertrieb | D7: Hamburg
A8: 1007 | B8: Orhan Siering MBA. | C8: IT | D8: Berlin
A9: 1008 | B9: Dipl.-Ing. Klaus-Werner Holsten B.Sc. | C9: IT | D9: Hamburg
A10: 1009 | B10: Univ.Prof. Heimo Karge | C10: Marketing | D10: Hamburg
A11: 1010 | B11: Carolin Hande | C11: IT | D11: Hamburg
A12: 1011 | B12: Auguste Davids | C12: IT | D12: Hamburg
A13: 1012 | B13: Ariane Klemt-Kaul | C13: IT | D13: München

Sheet Tabelle4
A1: Rückgabe am | B1: (Alle)

Sheet Tabelle3
A3: Summe von Netto-Kaufpreis
A4: 4190571

Sheet Geraete_Mitarbeiter_ID
A1: Gerätenummer | B1: Gerätetyp | C1: Modell | D1: Kaufdatum | E1: Netto-Kaufpreis | F1: Standort | G1: Ausleihen.Mitarbeiter-ID
A2: G0035 | B2: Beamer | C2: BenQ MW550 | D2: 45294 | E2: 64454 | F2: Berlin | G2: 1009
A3: G0035 | B3: Beamer | C3: BenQ MW550 | D3: 45294 | E3: 64454 | F3: Berlin | G3: 1003
A4: G0035 | B4: Beamer | C4: BenQ MW550 | D4: 45294 | E4: 64454 | F4: Berlin | G4: 1001
A5: G0021 | B5: Monitor | C5: Samsung Curved | D5: 44979 | E5: 113416 | F5: München | G5: 1008
A6: G0024 | B6: Monitor | C6: Dell UltraSharp | D6: 44621 | E6: 75091 | F6: Berlin | G6: 1005
A7: G0024 | B7: Monitor | C7: Dell UltraSharp | D7: 44621 | E7: 75091 | F7: Berlin | G7: 1008
A8: G0004 | B8: Laptop | C8: Dell XPS | D8: 45782 | E8: 100788 | F8: München | G8: 1003
A9: G0016 | B9: Drucker | C9: Canon Pixma | D9: 45015 | E9: 150106 | F9: Berlin | G9: 1010
A10: G0016 | B10: Drucker | C10: Canon Pixma | D10: 45015 | E10: 150106 | F10: Berlin | G10: 1002
A11: G0016 | B11: Drucker | C11: Canon Pixma | D11: 45015 | E11: 150106 | F11: Berlin | G11: 1003
A12: G0005 | B12: Drucker | C12: Canon Pixma | D12: 44503 | E12: 82323 | F12: Berlin | G12: 1009
A13: G0005 | B13: Drucker | C13: Canon Pixma | D13: 44503 | E13: 82323 | F13: Berlin | G13: 1006
... A46: G0006 | B46: Smartphone | C46: Samsung S21 | D46: 45292 | E46: 125796 | F46: München | G46: 1007
A48: G0001 | B48: Tablet | C48: Galaxy Tab | D48: 44937 | E48: 134283 | F48: Berlin
A49: G0002 | B49: Tablet | C49: Surface Go | D49: 44250 | E49: 107618 | F49: München
A50: G0003 | B50: Tablet | C50: iPad | D50: 45543 | E50: 193154 | F50: München
A51: G0008 | B51: Beamer | C51: Epson EB | D51: 45831 | E51: 132376 | F51: Hamburg
A52: G0010 | B52: Laptop | C52: Dell XPS | D52: 45239 | E52: 178637 | F52: München
A53: G0012 | B53: Tablet | C53: Galaxy Tab | D53: 44713 | E53: 96843 | F53: Hamburg
A54: G0017 | B54: Smartphone | C54: Samsung S21 | D54: 44363 | E54: 174856 | F54: Berlin
A55: G0019 | B55: Drucker | C55: HP LaserJet | D55: 44429 | E55: 73757 | F55: Hamburg
A56: G0020 | B56: Smartphone | C56: Samsung S21 | D56: 45297 | E56: 7402 | F56: München
A57: G0023 | B57: Drucker | C57: Canon Pixma | D57: 45249 | E57: 133534 | F57: Hamburg
A58: G0026 | B58: Laptop | C58: Dell XPS | D58: 45219 | E58: 140391 | F58: Hamburg
A59: G0034 | B59: Smartphone | C59: Samsung S21 | D59: 45552 | E59: 174667 | F59: Hamburg

Sheet Tabelle2
A3: Summe von Netto-Kaufpreis
A4: 6678200

Sheet Tabelle1
